Workbook
Name a_prop: Abaco!$G$43:$G$69
Name Acc_max: Trajecto!$L$25
Name acc_x: Calculs!$D$4:$D$1004
Name acc_xz: Calculs!$F$4:$F$1004
Name acc_z: Calculs!$E$4:$E$1004
Name Alt_para: Trajecto!$I$28
Name alt_prop: Abaco!$J$43:$J$69
Name Alt_rampe: Trajecto!$C$21
Name Alt_sat: Trajecto!$I$26
Name Altitude_culmi: Trajecto!$I$27
Name b_bal: Abaco!$I$43:$I$69
Name b_prop: Abaco!$H$43:$H$69
Name Beta: Calculs!$M$4:$M$1004
Name Beta_rampe: Trajecto!$C$20
Name BetaD: Calculs!$N$4:$N$1004
Name CdP: Propu!$B$3:$Y$4
Name CdP_P: Propu!$B$4:$Y$4
Name CdP_t: Propu!$B$3:$Y$3
Name Club: Stabilito!$C$9
Name Cn: Stabilito!$H$28
Name Cn0: Stabilito!$I$28
Name Cnai: Stabilito!$O$19
Name Cnai0: Stabilito!$P$19
Name Cnail: Stabilito!$O$20
Name Cnc: Stabilito!$O$21
Name Cni: Stabilito!$O$22
Name Cni0: Stabilito!$P$22
Name Cnj: Stabilito!$O$23
Name Cno: Stabilito!$O$18
Name Cnr: Stabilito!$O$24
Name Combustion: Propu!$X$2
Name CritCnmax: Stabilito!$J$28
Name CritCnmin: Stabilito!$G$28
Name CritFinessemax: Stabilito!$J$27
Name CritFinessemin: Stabilito!$G$27
Name CritMsCnmax: Stabilito!$J$30
Name CritMsCnmin: Stabilito!$G$30
Name CritMsmax: Stabilito!$J$29
Name CritMsmin: Stabilito!$G$29
Name Cx: Trajecto!$C$16
Name Cx_para: Trajecto!$C$30
Name Cx_satellite: Trajecto!$D$30
Name D_ail: Stabilito!$C$35
Name D_can: Stabilito!$D$35
Name D_int: Stabilito!$E$34
Name D_og: Stabilito!$C$24
Name D_ref: Stabilito!$C$15
Name D_var: Abaco!$B$43:$B$69
Name D1j: Stabilito!$M$7
Name D1r: Stabilito!$O$7
Name D2j: Stabilito!$M$8
Name D2r: Stabilito!$O$8
Name Débit: Calculs!$R$4:$R$1004
Name Depotage: Propu!$Z$2
Name Diam_propu: Propu!$T$2
Name Dt_para: Trajecto!$C$33
Name Dt_satellite: Trajecto!$D$33
Name Dx_para: Trajecto!$C$35
Name Dx_sat: Trajecto!$D$35
Name E_ail: Stabilito!$C$31

Sheet Stabilito
C2: STABILITO | L2: ="Language/Langue" -> Language/Langue | M2: Français
C4: =IF(Lang="Français","Stabilité de fusée à ailerons",IF(Lang="English","Stability for rocket with fins","")) -> Stabilité de fusée à ailerons | M4: Fusée mono-diamètre,
M5: Transition A | O5: Transition B
C6: =IF(Lang="Français","Remplir les cases jaunes",IF(Lang="English","Fill-in yellow cells only","")) -> Remplir les cases jaunes | L6: =IF(Lang="Français","Longueur 'L'",IF(Lang="English","Length 'L'","")) -> Longueur 'L' | M6: 50 | O6: 50
C7: =IF(Lang="Français","Fusée",IF(Lang="English","Rocket","")) -> Fusée | L7: =IF(Lang="Français","Diamètre 'D1'",IF(Lang="English","Diameter 'D1'","")) -> Diamètre 'D1' | M7: 84 | O7: 84
B8: =IF(Lang="Français","Nom",IF(Lang="English","Name","")) -> Nom | C8: SP02_BETA | L8: =IF(Lang="Français","Diamètre 'D2'",IF(Lang="English","Diameter 'D2'","")) -> Diamètre 'D2' | M8: 104 | O8: 104
B9: Club | C9: L'AéroIPSA | L9: =IF(Lang="Français","Implantation 'x'",IF(Lang="English","Basement 'x'","")) -> Implantation 'x' | M9: 1 | O9: 0
B10: Matricule | C10: =IF((LEFT(Type_fusee,4)="Mini"),"MF",(IF((RIGHT(Type_fusee,1)="."),"FX",""))) -> FX | D10: 0 | E10: =IF(C10="","",C10&D10) -> FX0
B11: Type | C11: Fusée expérimentale. | M11: =IF(Lang="Français","Propu plein",IF(Lang="English","Loaded Motor","")) -> Propu plein | N11: =IF(Lang="Français","Propu vide",IF(Lang="English","Empty Motor","")) -> Propu vide | P11: =IF(Lang="Français","Sans propu",IF(Lang="English","Without M","")) -> Sans propu | T11: =IF(Lang="Français","Propulseur",IF(Lang="English","Motor","")) -> Propulseur
B12: =IF(Lang="Français","Masse",IF(Lang="English","Weight","")) -> Masse | C12: 7800 | D12: sans propu | L12: =IF(Lang="Français","Masse propu",IF(Lang="English","Motor Mass","")) -> Masse propu | M12: =MpropuPlein -> 1.685 | N12: =MpropuVide -> 0.652 | P12: - | S12: =IF(Lang="Français","Haut",IF(Lang="English","Top","")) -> Haut | T12: =XpropuRef-Long_propu -> 862
B13: =IF(Lang="Français","Centre de Masse",IF(Lang="English","Center of Mass","")) -> Centre de Masse | C13: 827 | D13: sans propu | L13: =IF(Lang="Français","CdM propu",IF(Lang="English","Motor CoM","")) -> CdM propu | M13: =XpropuPlein -> 250 | N13: =XpropuVide -> 240 | P13: - | S13: =IF(Lang="Français","Longueur",IF(Lang="English","Length","")) -> Longueur | T13: =Long_propu -> 488
B14: =IF(Lang="Français","Longueur totale",IF(Lang="English","Total length","")) -> Longueur totale | C14: 1410 | L14: =IF(Lang="Français","Masse fusée",IF(Lang="English","Rocket Mass","")) -> Masse fusée | M14: =MasseSans+MpropuPlein -> 9.485 | N14: =MasseSans+MpropuVide -> 8.452 | P14: =IF(OR(D12="sans propu",D12="without motor"),C12/1000,IF(OR(D12="avec propu vide",D12="with empty motor"),C12/1000-MpropuVide,IF(OR(D12="avec propu plein",D12="with loaded motor"),C12/1000-MpropuPlein,"Erreur"))) -> 7.8 | S14: =IF(Lang="Français","Bas",IF(Lang="English","Base","")) -> Bas | T14: =XpropuRef -> 1350
B15: =IF(Lang="Français","Diamètre Réf.",IF(Lang="English","Ref. Diameter","")) -> Diamètre Réf. | C15: =D_og -> 84 | L15: =IF(Lang="Français","CdM fusée",IF(Lang="English","Rocket CoM","")) -> CdM fusée | M15: =(XcgSans*MasseSans+(XpropuRef-Long_propu+XpropuPlein)*MpropuPlein)/MassePlein -> 877.62994 | N15: =(XcgSans*MasseSans+(XpropuRef-Long_propu+XpropuVide)*MpropuVide)/MasseVide -> 848.21391 | P15: =IF(OR(D13="sans propu",D13="without motor"),C13,IF(OR(D13="avec propu vide",D13="with empty motor"),(C13*MasseVide-(XpropuRef-Long_propu+XpropuVide)*MpropuVide)/MasseSans,IF(OR(D13="avec propu plein",D13="with loaded motor"),(C13*MassePlein-(XpropuRef-Long_propu+XpropuPlein)*MpropuPlein)/MasseSans,"Erreur"))) -> 827
T16: =IF(RIGHT(Type_masquage,1)=",",IF(Lang="Français","Ailerons","Fins"),IF(Lang="Français","Ailerons bas","Lower Fins")) -> Ailerons bas
C17: =IF(Lang="Français","Propulseur",IF(Lang="English","Motor","")) -> Propulseur | M17: XCp | O17: Cnα | S17: =IF(Lang="Français","Haut","Top") -> Haut | T17: =X_ail-m_ail -> 1230
B18: Type | C18: Barasinga (Pro54-5G C) | L18: =IF(Lang="Français","Coiffe",IF(Lang="English","Nose Cone","")) -> Coiffe | M18: =IF(LEFT(Forme_ogive,5)="Parab",1/2*Long_ogive,IF(LEFT(Forme_ogive,4)="Ogiv",7/15*Long_ogive,IF(LEFT(Forme_ogive,3)="Con",2/3*Long_ogive))) -> 183.33333 | O18: =2*POWER(D_og/D_ref, 2) -> 2 | S18: =IF(Lang="Français","Emplanture","Root edge") -> Emplanture | T18: =m_ail -> 180
B19: =IF(Lang="Français","Position du bas",IF(Lang="English","Basement","")) -> Position du bas | C19: 1350 | L19: =IF(Lang="Français","Ailerons",IF(Lang="English","Fins","")) -> Ailerons | M19: =(XCpa*Cnail-0.5*XCpi*Cni)/Cnai -> 1333.8462 | O19: =Cnail-Cni/2 -> 13.682157 | S19: =IF(Lang="Français","Bas","Base") -> Bas | T19: =X_ail -> 1410
B20: =IF(Propu="Cariacou","Cariacou :"," ") | C20: =IF(Propu="Pandora (Pro24-6G)",IF(Lang="Français","C'Space Seulement",IF(Lang="English","C'Space only","")),"") | L20: =IF(Lang="Français","Ail bas entier",IF(Lang="English","Total Lower Fins","")) -> Ail bas entier | M20: =X_ail-m_ail+p_ail*(m_ail+2*n_ail)/(3*(m_ail+n_ail))+(m_ail+n_ail-m_ail*n_ail/(m_ail+n_ail))/6 -> 1333.8462 | O20: =4*Q_ail*POWER((E_ail/D_ref),2)*(1+D_ail/(2*E_ail+D_ail))/(1+SQRT(1+POWER(2*f_ail/(m_ail+n_ail),2))) -> 13.682157
C21: =IF(Lang="Français","Coiffe",IF(Lang="English","Nose Cone","")) -> Coiffe | L21: =IF(Lang="Français","Ailerons haut",IF(Lang="English","Upper Fins","")) -> Ailerons haut | M21: =IF(LEFT(Type_masquage,1)="M",0, X_can-m_can+p_can*(m_can+2*n_can)/(3*(m_can+n_can))+(m_can+n_can-m_can*n_can/(m_can+n_can))/6) -> 0 | O21: =IF(LEFT(Type_masquage,1)="M",0, 4*Q_can*POWER((E_can/D_ref),2)*(1+D_can/(2*E_can+D_can))/(1+SQRT(1+POWER(2*f_can/(m_can+n_can),2)))) -> 0
B22: =IF(Lang="Français","Forme",IF(Lang="English","Shape","")) -> Forme | C22: Conique (droite) | L22: =IF(Lang="Français","Partie masquée",IF(Lang="English","Interation zone","")) -> Partie masquée | M22: =IF(LEFT(Type_masquage,1)="B", X_int-m_int+p_int*(m_int+2*n_int)/(3*(m_int+n_int))+(m_int+n_int-m_int*n_int/(m_int+n_int))/6, 0 ) -> 0 | O22: =IF(LEFT(Type_masquage,1)="B", 4*Q_int*POWER((E_int/D_ref),2)*(1+D_int/(2*E_int+D_int))/(1+SQRT(1+POWER(2*f_int/(m_int+n_int),2))), 0 ) -> 0
B23: =IF(Lang="Français","Hauteur",IF(Lang="English","Heigth","")) -> Hauteur | C23: 275 | L23: Transition A | M23: =IF(OR(RIGHT(Nb_diam,1)=",",D2j=0),0, X_j+l_j/3*(1+1/(1+D1j/D2j)) ) -> 0 | O23: =IF(OR(RIGHT(Nb_diam,1)=",",D2j=0),0,2*(POWER(D2j/D_ref,2)-POWER(D1j/D_ref,2))) -> 0
B24: =IF(Lang="Français","Diamètre",IF(Lang="English","Diameter","")) -> Diamètre | C24: 84 | L24: Transition B | M24: =IF( OR(RIGHT(Nb_diam,1)=",",D2r=0), 0, X_r+l_r/3*(1+1/(1+D1r/D2r)) ) -> 0 | O24: =IF( OR(RIGHT(Nb_diam,1)=",",D2r=0), 0, 2*(POWER(D2r/D_ref,2)-POWER(D1r/D_ref,2)) ) -> 0
E25: M | S25: =IF(AND(Portee_balistique>200,LEFT(Type_propu,3)="Min"),IF(Lang="Français","Fusée trop lègère !","Rocket too light"),"")
C26: =IF(LEFT(Type_masquage,1)="M",IF(Lang="Français","Ailerons","Fins"),IF(Lang="Français","Ailerons bas","Lower Fins")) -> Ailerons | D26: =IF(Lang="Français","Ailerons haut",IF(Lang="English","Upper Fins","")) -> Ailerons haut | F26: =TODAY() -> 45890 | G26: Min | H26: =IF(Lang="Français","Résultats",IF(Lang="English","Results","")) -> Résultats | J26: Max | S26: =IF(AND(Vsortie_de_rampe<18, OR(LEFT(Type_fusee,1)=",",LEFT(Type_fusee,4)="Mini",LEFT(Type_fusee,1)="R")),IF(Lang="Français","Fusée trop lourde ou rampe trop courte !","Rocket too heavy or launch pad too small!"),"") -> #N/A
C27: Mono-empennage | E27: =m_ail -> 180 | F27: Finesse | G27: =IF(RIGHT(Type_fusee,1)=".",10, IF(OR(LEFT(Type_fusee,1)="R",LEFT(Type_fusee,1)=",",LEFT(Type_fusee,4)="Mini"),10, IF(LEFT(Type_fusee,5)="Micro",10, IF(RIGHT(Type_fusee,1)=" ",1)))) -> 10 | H27: =Long_tot/D_ref -> 16.785714 | J27: =IF(RIGHT(Type_fusee,1)=".",35, IF(OR(LEFT(Type_fusee,1)="R",LEFT(Type_fusee,1)=",",LEFT(Type_fusee,4)="Mini"),20, IF(LEFT(Type_fusee,5)="Micro",30, IF(RIGHT(Type_fusee,1)=" ",100)))) -> 35 | S27: =IF(Finesse<CritFinessemin, IF(Lang="Français","Fusée trop courte !","Rocket too short!"), "" ) & IF(Finesse>CritFinessemax, IF(Lang="Français","Fusée trop longue !","Rocket too long!"), "" )
B28: =IF(Lang="Français"," Emplanture 'm'",IF(Lang="English"," Root edge 'm'","")) -> Emplanture 'm' | C28: 180 | D28: 70 | E28: =n_ail+(m_ail-n_ail)*(1-E_int/E_ail) -> 134.54545 | F28: =IF(Lang="Français","Portance","Lift") -> Portance | G28: =IF(RIGHT(Type_fusee,1)=".",15,IF(OR(LEFT(Type_fusee,1)="R",LEFT(Type_fusee,1)=",",LEFT(Type_fusee,4)="Mini"),15, IF(LEFT(Type_fusee,5)="Micro",15, IF(RIGHT(Type_fusee,1)=" ",15)))) -> 15 | H28: =Cnai+Cnc+Cno+Cnj+Cnr -> 15.682157 | I28: =Cnail+Cnc+Cno+Cnj+Cnr -> 15.682157 | J28: =IF(RIGHT(Type_fusee,1)=".",40, IF(OR(LEFT(Type_fusee,1)="R",LEFT(Type_fusee,1)=",",LEFT(Type_fusee,4)="Mini"),30, IF(LEFT(Type_fusee,5)="Micro",30, IF(RIGHT(Type_fusee,1)=" ",30)))) -> 40 | S28: =IF(Cn<CritCnmin, IF(Lang="Français","Ailerons trop petits !","Fins too small!"), "" ) & IF(Cn>CritCnmax, IF(Lang="Français","Ailerons trop grands !","Fins too big!"), "" )
B29: =IF(Lang="Français"," Saumon 'n'",IF(Lang="English"," Tip edge 'n'","")) -> Saumon 'n' | C29: 80 | D29: 10 | E29: =p_ail*E_int/E_ail -> 72.727273 | F29: =IF(Lang="Français","MargeStat.","StatMargin") -> MargeStat. | G29: =IF(RIGHT(Type_fusee,1)=".",2, IF(OR(LEFT(Type_fusee,1)="R",LEFT(Type_fusee,1)=",",LEFT(Type_fusee,4)="Mini"),1.5, IF(LEFT(Type_fusee,5)="Micro",1, IF(RIGHT(Type_fusee,1)=" ",1)))) -> 2 | H29: =(XCp-XcgPlein)/D_ref -> 3.6843727 | I29: =(XCp0-XcgVide)/D_ref -> 4.0345635 | J29: =IF(RIGHT(Type_fusee,1)=".",6, IF(OR(LEFT(Type_fusee,1)="R",LEFT(Type_fusee,1)=",",LEFT(Type_fusee,4)="Mini"),6, IF(LEFT(Type_fusee,5)="Micro",3, IF(RIGHT(Type_fusee,1)=" ",3)))) -> 6 | S29: =IF(MS_min<CritMsmin, IF(Lang="Français","Abaisser les ailerons ou rehausser le CdM !","Lower the fins or move up the center of mass!"), "" ) & IF(MS_max>CritMsmax, IF(Lang="Français","Rehausser les ailerons ou abaisser le CdM !","Move up the fins or lower the center of mass!"), "" )
B30: =IF(Lang="Français"," Flèche 'p'"," Offset 'p'") -> Flèche 'p' | C30: 160 | D30: 40 | E30: =IF(D_can/2+E_can<=D_ail/2,0, IF(D_can/2+E_can>=D_ail/2+E_ail,E_ail, D_can/2+E_can - D_ail/2 ) ) -> 50 | F30: =IF(Lang="Français","Couple","Torque") -> Couple | G30: =IF(RIGHT(Type_fusee,1)=".",40, IF(OR(LEFT(Type_fusee,1)="R",LEFT(Type_fusee,1)=",",LEFT(Type_fusee,4)="Mini"),30, IF(LEFT(Type_fusee,5)="Micro",15, IF(RIGHT(Type_fusee,1)=" ",15)))) -> 40 | H30: =MS_min*Cn -> 57.778909 | I30: =MS_max*Cn0 -> 63.270657 | J30: =IF(RIGHT(Type_fusee,1)=".",100, IF(OR(LEFT(Type_fusee,1)="R",LEFT(Type_fusee,1)=",",LEFT(Type_fusee,4)="Mini"),100, IF(LEFT(Type_fusee,5)="Micro",100, IF(RIGHT(Type_fusee,1)=" ",90)))) -> 100 | S30: =IF(MS_Cn_min<CritMsCnmin, IF(Lang="Français","Ailerons trop petits ou trop haut /CdM !","Fins too small or too high /CoM!"), "" ) & IF(MS_Cn_max>CritMsCnmax, IF(Lang="Français","Ailerons trop grands ou trop bas /CdM !","Fins too big or too low / CoM!"), "" )
B31: =IF(Lang="Français"," Envergure 'E'",IF(Lang="English"," Span 'E'","")) -> Envergure 'E' | C31: 110 | D31: 50 | E31: =ep_ail -> 4 | F31: XCp | H31: =(Cnai*XCpai+Cnc*XCpc+Cnj*XCpj+Cnr*XCpr+Cno*XCpo)/(Cnai+Cnc+Cnr+Cnj+Cno) -> 1187.1172 | I31: =(Cnail*XCpa+Cnc*XCpc+Cnj*XCpj+Cnr*XCpr+Cno*XCpo)/(Cnail+Cnc+Cnr+Cnj+Cno) -> 1187.1172
B32: =IF(Lang="Français"," Epaisseur 'ep'",IF(Lang="English"," Thickness 'ep'","")) -> Epaisseur 'ep' | C32: 4 | D32: 2 | E32: =IF(Q_ail=Q_can,Q_ail,FALSE) -> 4 | F32: MS /L | H32: =(XCp-XcgPlein)/Long_tot*100 -> 21.949454 | I32: =(XCp-XcgVide)/Long_tot*100 -> 24.035698
B33: =IF(Lang="Français"," Nombre ",IF(Lang="English"," Number of fins","")) -> Nombre | C33: 4 | D33: 4 | E33: =X_ail -> 1410 | H33: =IF(AND(CritCnmin<Cn,Cn0<CritCnmax,CritMsmin<MS_min,MS_max<CritMsmax,CritMsCnmin<MS_Cn_min,MS_Cn_max<CritMsCnmax),"STABLE",IF(OR(Cn<CritCnmin,MS_min<CritMsmin,MS_Cn_min<CritMsCnmin),"INSTABLE",IF(Lang="Français","SURSTABLE","OVERSTABLE"))) -> STABLE
B34: =IF(Lang="Français"," Position du bas",IF(Lang="English"," Basement","")) -> Position du bas | C34: 1410 | D34: 700 | E34: =D_ail -> 84
B35: =IF(Lang="Français"," Diamètre ",IF(Lang="English"," Diameter at Fins","")) -> Diamètre | C35: =D_ref -> 84 | D35: =D_ref -> 84 | E35: =SQRT(POWER(p_int+n_int/2-m_int/2,2)+POWER(E_int,2)) -> 70.710678 | W35: =RIGHT(Type_fusee,1="R")
B36: =IF(Lang="Français"," Ligne mi-corde f",IF(Lang="English"," Mid-chord line f","")) -> Ligne mi-corde f | C36: =SQRT(POWER(p_ail+n_ail/2-m_ail/2,2)+POWER(E_ail,2)) -> 155.56349 | D36: =SQRT(POWER(p_can+n_can/2-m_can/2,2)+POWER(E_can,2)) -> 50.990195
B37: =IF(Lang="Français","Commentaire libre :",IF(Lang="English","Free comment:","")) -> Commentaire libre : | L37: Checksum : | M37: =IF(ROUND(SUM(Propu!5:1228),0)=437735,"propu OK","propu NOK") -> propu OK | N37: =IF(Lang="Français","fichier initial","Initial file") -> fichier initial | Q37: v3.4.5
L39: =IF(Lang="Français","Maintenant que votre fusée est stable, vérifiez sa trajectoire via la feuille","Now your rocket is stable, check its trajectory on sheet") -> Maintenant que votre fusée est stable, vérifiez sa trajectoire via la feuille | M39: Trajecto
B92: =IF(Lang="Français","Textes pour les listes déroulantes et graphiques :",IF(Lang="English","Texts for drop-down lists & graphics :","")) -> Textes pour les listes déroulantes et graphiques :
B94: Français
B95: English
B97: =IF(Lang="Français","Fusée à eau ",IF(Lang="English","Water-rocket ","")) -> Fusée à eau
...

Sheet Trajecto
C2: TRAJECTO
C4: =IF(Lang="Français","Trajectographie de fusée",IF(Lang="English","Rocket Trajectography","")) -> Trajectographie de fusée
C6: =IF(Lang="Français","Remplir les cases jaunes",IF(Lang="English","Fill-in yellow cells only","")) -> Remplir les cases jaunes
C7: =IF(Lang="Français","Fusée",IF(Lang="English","Rocket","")) -> Fusée
B8: =IF(Lang="Français","Nom",IF(Lang="English","Name","")) -> Nom | C8: =Nom -> SP02_BETA
B9: Club | C9: =Club -> L'AéroIPSA
B10: Matricule | C10: =Matricule -> FX0
B11: =IF(Lang="Français","Masse totale",IF(Lang="English","Total Mass","")) -> Masse totale | C11: =MassePlein -> 9.485
B12: =IF(Lang="Français","Propulseur",IF(Lang="English","Motor","")) -> Propulseur | C12: =Propu -> Barasinga (Pro54-5G C)
C14: =IF(Lang="Français","Traînée Aérdynamique",IF(Lang="English","Drag","")) -> Traînée Aérdynamique
B15: Surface Réf. | C15: =(PI()*D_ref^2/4+E_ail*ep_ail*Q_ail)/10^6 -> 0.0073017694
B16: Cx | C16: 0.6
C18: =IF(Lang="Français","Rampe de Lancement",IF(Lang="English","Launch Pad","")) -> Rampe de Lancement
B19: =IF(Lang="Français","Longueur",IF(Lang="English","Length","")) -> Longueur | C19: =IF(RIGHT(Type_fusee,1)=".",4, IF(LEFT(Type_fusee,4)="Mini",2.5, IF(LEFT(Type_fusee,5)="Micro",1, IF(RIGHT(Type_fusee,1)=" ",0.1,IF(LEFT(Type_fusee,1)="R",3, 2.5))))) -> 4
B20: =IF(Lang="Français","Élévation",IF(Lang="English","Angle /horizon","")) -> Élévation | C20: 72.642008
B21: Altitude | C21: 0
F22: =IF( OR( AND(Vsortie_de_rampe<18, RIGHT(Type_fusee,1)=";"), AND(Vsortie_de_rampe<20, RIGHT(Type_fusee,1)=".")), IF(Lang="Français","Vitesse en Sortie de Rampe trop faible, alléger la fusée ou choisir un propu plus puissant.","Speed at Launch Pad Exit too low, lighten the rocket or choose a bigger motor."), "") -> #N/A
C23: =IF(Lang="Français","DescenteSousParachute",IF(Lang="English","Over Parachute","")) -> DescenteSousParachute | G23: =TODAY() -> 45890 | H23: =IF(Lang="Français","Temps",IF(Lang="English","Time","")) -> Temps | I23: Altitude z | J23: =IF(Lang="Français","Portée x",IF(Lang="English","Range x","")) -> Portée x | K23: =IF(Lang="Français","Vitesse",IF(Lang="English","Velocity","")) -> Vitesse | L23: Accélération | M23: Efforts
C24: =C7 -> Fusée | D24: 0 satellite | E24: =IF(ABS(T_satellite-0.11-T_para)<0.1,"Pb!","") | F24: =IF(Lang="Français","Sortie de Rampe",IF(Lang="English","Launch-Pad Exit","")) -> Sortie de Rampe | K24: =INDEX(vit_xz,MATCH("Sortie de rampe",Event,0)) -> #N/A
B25: =IF(Lang="Français","Masse",IF(Lang="English","Mass","")) -> Masse | C25: =IF(Nb_sat="0 satellite",MasseVide,MasseVide-m_satellite) -> 8.452 | D25: =IF(RIGHT(Type_fusee,1)=".",1,0.15) -> 1 | F25: =IF(Lang="Français","Vit max & Acc max",IF(Lang="English","Max Velocity & Acc","")) -> Vit max & Acc max | K25: =MAX(vit_xz) -> 238.2867 | L25: =MAX(acc_xz) -> 83.369808
B26: =IF(Lang="Français","Dépotage",IF(Lang="English","Delay","")) -> Dépotage | C26: N/A | F26: =IF(Lang="Français","Largage du satellite",IF(Lang="English","Satellite separation","")) -> Largage du satellite | H26: =IF(T_satellite<>0,T_satellite,"") -> 3.5 | I26: =IF(T_satellite<>0,INDEX(pos_z,MATCH("Satellite",Event_sat,0)),"") -> #N/A | J26: =IF(T_satellite<>0,INDEX(pos_x,MATCH("Satellite",Event_sat,0)),"") -> #N/A | K26: =IF(T_satellite<>0,INDEX(vit_xz,MATCH("Satellite",Event_sat,0)),"") -> #N/A | M26: =1/2*Rho_moyen*1*V_ouv_sat^2*S_satellite -> #N/A
B27: =IF(Lang="Français","Ouverture para",IF(Lang="English","Opening time","")) -> Ouverture para | C27: 21.7 | D27: 3.5 | F27: Culmination, Apogée | H27: =INDEX(t,MATCH("Apogée",Event,0)) -> 23.2 | I27: =INDEX(pos_z,MATCH("Apogée",Event,0)) -> 2430.751 | J27: =INDEX(pos_x,MATCH("Apogée",Event,0)) -> 1310.482 | K27: =INDEX(vit_xz,MATCH("Apogée",Event,0)) -> 52.227679
B28: Type de para | C28: Croix | F28: =IF(Lang="Français","Ouverture parachute fusée",IF(Lang="English","Rocket parachute opening","")) -> Ouverture parachute fusée | H28: =T_para -> 21.7 | I28: =INDEX(pos_z,MATCH("Para",Event_para,0)) -> 2418.9069 | J28: =INDEX(pos_x,MATCH("Para",Event_para,0)) -> 1231.3628 | K28: =INDEX(vit_xz,MATCH("Para",Event_para,0)) -> 55.452447 | M28: =1/2*Rho_moyen*1*V_ouverture^2*S_para -> 904.98404 | P28: =IF(V_para<5, IF(Lang="Français","Parachute fusée trop grand !","Parachute too big!"), IF( V_para>15, IF(Lang="Français","Parachute fusée trop petit !","Parachute too small!"), "")) -> Parachute fusée trop petit ! | R28: =IF(AND(Nb_sat="1 satellite", OR(V_satellite<5)), IF(Lang="Français","Parachute satéllite trop grand !","Parachute too big"), IF(AND(Nb_sat="1 satellite",OR(V_satellite>15)), IF(Lang="Français","Parachute satéllite trop petit !","Parachute too small!"), ""))
B29: Surface para | C29: =IF(C28="rond",S_para_rond,IF(C28="Croix",S_para_croix,0.5)) -> 0.4805 | D29: =IF(RIGHT(Type_fusee,1)=".",0.1,0.02) -> 0.1 | F29: =IF(Lang="Français","Impact balistique",IF(Lang="English","Balistic Impact","")) -> Impact balistique | H29: =INDEX(t,MATCH("Impact balistique",Event,0)) -> 48.3 | I29: ~0 m | J29: =INDEX(pos_x,MATCH("Impact balistique",Event,0)) -> 2310.0931 | K29: =K47 -> 159.74319 | M29: =0.5*m_vide*K29^2 -> 107838.59 | P29: =IF( OR( V_para<5, V_para>15, AND(Nb_sat="1 satellite", OR(V_satellite<5, V_satellite>15))), IF(Lang="Français","La Vitesse de descente sous parachute doit être comprise entre 5 & 15 m/s.","Fall Velocity with parachute must be between 5 & 15 m/s."), "") -> La Vitesse de descente sous parachute doit être comprise entre 5 & 15 m/s.
B30: Cx parachute | C30: 1 | D30: 1 | E30: =IF(AND(T_satellite=0,m_satellite<>0),"Erreur !","") | P30: =IF(AND(Portee_balistique>200,LEFT(Type_propu,4)="Mini"),IF(Lang="Français","Fusée trop lègère !","Rocket too light"),"")
B31: =IF(Lang="Français","Vitesse du vent",IF(Lang="English","Wind speed","")) -> Vitesse du vent | C31: 5 | D31: =V_vent -> 5 | P31: =IF(OR(AND(Vsortie_de_rampe<20,LEFT(Type_fusee,1)="F"),AND(Vsortie_de_rampe<18, OR(LEFT(Type_fusee,1)=",",LEFT(Type_fusee,4)="Mini",LEFT(Type_fusee,1)="R"))),IF(Lang="Français","Fusée trop lourde ou rampe trop courte !","Rocket too heavy or launch pad too small!"),"") -> #N/A
B32: =IF(Lang="Français","Vitesse descente",IF(Lang="English","Fall velocity","")) -> Vitesse descente | C32: =SQRT(2*m_vide*g/Rho_moyen/S_para/Cx_para) -> 16.784736 | D32: =SQRT(2*m_satellite*g/Rho_moyen/S_satellite/Cx_satellite) -> 12.655563 | P32: =IF(Temps_culmi-T_para>2,IF(Lang="Français","Ouverture parachute fusée précoce.","Early rocket parachute opening."),IF(Temps_culmi-T_para<-2,IF(Lang="Français","Ouverture parachute fusée tardive.","Late rocket parachute opening."),""))
B33: =IF(Lang="Français","Durée descente",IF(Lang="English","Fall duration","")) -> Durée descente | C33: =Alt_para/V_para -> 144.11349 | D33: =IF(V_satellite<>0,Alt_sat/V_satellite,0) -> #N/A | H33: =IF(Lang="Français","Pour localiser la fusée","To locate the rocket") -> Pour localiser la fusée | P33: =IF(ABS(Temps_culmi-T_para)>2,IF(Lang="Français","Attention, aux efforts sur le parachute lors de l'ouverture !","Becarefull to the opening chute efforts!"),"")
B34: =IF(Lang="Français","Durée du vol",IF(Lang="English","Fligth duration","")) -> Durée du vol | C34: =T_para+Dt_para -> 165.81349 | D34: =T_satellite+Dt_satellite -> #N/A | F34: =IF(Lang="Français","Couleur fuselage/coiffe","Body/Nose color") -> Couleur fuselage/coiffe | H34: Brun/Orange…
B35: =IF(Lang="Français","Déport latéral",IF(Lang="English","Lateral shift","")) -> Déport latéral | C35: =Alt_para*V_vent/V_para -> 720.56746 | D35: =IF(V_satellite<>0,Alt_sat*V_vent_sat/V_satellite,0) -> #N/A | F35: =IF(Lang="Français","Couleur parachute fusée","Rocket parachute color") -> Couleur parachute fusée | H35: Rouge… | N35: =IF(Lang="Français","fichier initial","Initial file") -> fichier initial
F36: =IF(Lang="Français","Couleur parachute satellite","Satellite parachute color") -> Couleur parachute satellite | H36: Jaune | N36: =IF(ROUND(SUM(Propu!5:1228),0)=437735,"propu OK","propu NOK") -> propu OK
B37: =IF(Lang="Français","Commentaire libre :",IF(Lang="English","Free comment:","")) -> Commentaire libre : | N37: v3.4.5
A40: =IF(Lang="Français","Calcul de la surface d'un parachute","Parachute surface calculation") -> Calcul de la surface d'un parachute | F40: =IF(Lang="Français","Résultats détaillés","Detailled results") -> Résultats détaillés | H40: =IF(Lang="Français","Temps",IF(Lang="English","Time","")) -> Temps | I40: Altitude z | J40: =IF(Lang="Français","Portée x",IF(Lang="English","Range x","")) -> Portée x | K40: =IF(Lang="Français","Vitesse",IF(Lang="English","Velocity","")) -> Vitesse | L40: Accélération | M40: Angle
H41: s | I41: m | J41: m | K41: m/s | L41: m/s² | M41: °
F42: =IF(Lang="Français","Décollage",IF(Lang="English","Lift-Off","")) -> Décollage | H42: 3.7 | I42: 353.9867 | J42: 86.435214 | K42: 72.694334 | L42: - | M42: =Beta_rampe -> 72.642008
B43: =IF(Lang="Français","Bord 'a'","Side length 'a'") -> Bord 'a' | F43: =IF(Lang="Français","Sortie de Rampe",IF(Lang="English","Launch-Pad Exit","")) -> Sortie de Rampe | H43: =INDEX(t,MATCH("Sortie de rampe",Event,0)) -> #N/A | I43: =INDEX(pos_z,MATCH("Sortie de rampe",Event,0)) -> #N/A | J43: =INDEX(pos_x,MATCH("Sortie de rampe",Event,0)) -> #N/A | K43: =INDEX(vit_xz,MATCH("Sortie de rampe",Event,0)) -> #N/A | L43: =INDEX(acc_xz,MATCH("Sortie de rampe",Event,0)) -> #N/A | M43: =INDEX(BetaD,MATCH("Sortie de rampe",Event,0)) -> #N/A
B44: 310 | F44: =IF(Lang="Français","Vit max & Acc max",IF(Lang="English","Max Velocity & Acc","")) -> Vit max & Acc max | H44: - | I44: - | J44: - | K44: =MAX(vit_xz) -> 238.2867 | L44: =MAX(acc_xz) -> 83.369808 | M44: -
B45: =IF(Lang="Français","Coté 'b'","Side width 'b'") -> Coté 'b' | F45: =IF(Lang="Français","Fin de Propulsion",IF(Lang="English","Motor Burn-Out","")) -> Fin de Propulsion | H45: =INDEX(t,MATCH("Fin de propulsion",Event,0)) -> 7.3 | I45: =INDEX(pos_z,MATCH("Fin de propulsion",Event,0)) -> 960.66101 | J45: =INDEX(pos_x,MATCH("Fin de propulsion",Event,0)) -> 308.44346 | K45: =INDEX(vit_xz,MATCH("Fin de propulsion",Event,0)) -> 233.27091 | L45: =INDEX(acc_xz,MATCH("Fin de propulsion",Event,0)) -> 25.114887 | M45: =INDEX(BetaD,MATCH("Fin de propulsion",Event,0)) -> 68.474971
B46: 310 | F46: Culmination, Apogée | H46: =INDEX(t,MATCH("Apogée",Event,0)) -> 23.2 | I46: =INDEX(pos_z,MATCH("Apogée",Event,0)) -> 2430.751 | J46: =INDEX(pos_x,MATCH("Apogée",Event,0)) -> 1310.482 | K46: =INDEX(vit_xz,MATCH("Apogée",Event,0)) -> 52.227679 | L46: =INDEX(acc_xz,MATCH("Apogée",Event,0)) -> 9.8525407 | M46: =INDEX(BetaD,MATCH("Apogée",Event,0)) -> 0.52607457
B47: Surface para | F47: =IF(Lang="Français","Impact balistique",IF(Lang="English","Balistic Impact","")) -> Impact balistique | H47: =INDEX(t,MATCH("Impact balistique",Event,0)) -> 48.3 | I47: ~0 | J47: =INDEX(pos_x,MATCH("Impact balistique",Event,0)) -> 2310.0931 | K47: =INDEX(vit_xz,MATCH("Impact balistique",Event,0)) -> 159.74319 | L47: =INDEX(acc_xz,MATCH("Impact balistique",Event,0)) -> 2.209189 | M47: =INDEX(BetaD,MATCH("Impact balistique",Event,0)) -> -81.254787
...

Sheet Courbes
B75: Notes :
B76: =IF(Lang="Français","Ces courbes représentent la trajectoire de la fusée dans l'hypothèse d'une descente balistique (sans ouverture du parachute). ","These curves show the rocket trajectory in case of ballistic fall (without parachute).") -> Ces courbes représentent la trajectoire de la fusée dans l'hypothèse d'une descente balistique (sans ouverture du parachute).
B77: =IF(Lang="Français","L'accélération longitudinale gravitationnelle définit le mouvement (dérivée de la vitesse) : Acc = (Poussee - Traînée ± Poids) / m",IF(Lang="English","Longitudinal Gravitaionnal Acceleration defines the motion (velocity derivative) : Acc = (Thrust - Drag ± Weight)/m","")) -> L'accélération longitudinale gravitationnelle définit le mouvement (dérivée de la vitesse) : Acc = (Poussee - Traînée ± Poids) / m
B78: =IF(Lang="Français","La charge ''non-gravitationnelle'' vue par un capteur d'accélération (masse-ressort) est : Charge = (Poussée - Traînée) / m",IF(Lang="English","''Non-Gravitaionnal'' Load seen by an acceleration sensor (mass-spring) is : Load = (Thrust - Drag) / m","")) -> La charge ''non-gravitationnelle'' vue par un capteur d'accélération (masse-ressort) est : Charge = (Poussée - Traînée) / m
B79: =IF(Lang="Français","Exemples : Si Poussée = Poids, Vitesse constante, Acc nulle, Charge = 1G ; En chute libre, Acc = -1G, Charge = 0",IF(Lang="English","","")) -> Exemples : Si Poussée = Poids, Vitesse constante, Acc nulle, Charge = 1G ; En chute libre, Acc = -1G, Charge = 0
B131: =IF(Lang="Français","Textes pour les graphiques :","Texts for graphics :") -> Textes pour les graphiques :
B133: =IF(Lang="Français","Traînée",IF(Lang="English","Drag","")) -> Traînée
B134: =IF(Lang="Français","Poussée",IF(Lang="English","Thrust","")) -> Poussée
B135: =IF(Lang="Français","Poids",IF(Lang="English","Weight","")) -> Poids
B137: =IF(Lang="Français","Accélération longitudinale",IF(Lang="English","Longitudinal Acceleration","")) -> Accélération longitudinale
B138: =IF(Lang="Français","Charge vue par un capteur",IF(Lang="English","Load seen by a sensor","")) -> Charge vue par un capteur
B140: =IF(Lang="Français","Vitesse",IF(Lang="English","Velocity","")) -> Vitesse
B141: =IF(Lang="Français","Vitesse [m/s]",IF(Lang="English","Velocity [m/s]","")) -> Vitesse [m/s]
B143: Altitude
B144: =IF(Lang="Français","Portée",IF(Lang="English","Range","")) -> Portée
B146: =IF(Lang="Français","Temps [s]",IF(Lang="English","Time [s]","")) -> Temps [s]

Sheet Propu
A1: =IF(Lang="Français","Moteur sélectionné","Selected motor") -> Moteur sélectionné | B1: Ligne
A2: =Propu -> Barasinga (Pro54-5G C) | B2: =VLOOKUP(A2,A26:B314,2,FALSE) -> 279 | C2: I_total | D2: =INDIRECT(ADDRESS(B2,4)) -> 2058.37 | E2: ISP | F2: =INDIRECT(ADDRESS(B2,6)) -> 203.12067 | G2: MpropuPlein | H2: =INDIRECT(ADDRESS(B2,8)) -> 1.685 | I2: m_poudre | J2: =INDIRECT(ADDRESS(B2,10)) -> 1.033 | K2: MpropuVide | L2: =INDIRECT(ADDRESS(B2,12)) -> 0.652 | M2: XpropuPlein | N2: =INDIRECT(ADDRESS(B2,14)) -> 250 | O2: XpropuVide | P2: =INDIRECT(ADDRESS(B2,16)) -> 240 | Q2: Longueur | R2: =INDIRECT(ADDRESS(B2,18)) -> 488 | S2: Diamètre | T2: =INDIRECT(ADDRESS(B2,20)) -> 54 | U2: Type | V2: =INDIRECT(ADDRESS(B2,22)) -> Fusex | W2: Combustion | X2: =INDIRECT(ADDRESS(B2,24)) -> 0 | Y2: Dépotage | Z2: =INDIRECT(ADDRESS(B2,26)) -> 0
A3: =IF(Lang="Français","Temps (en s)","Time (s)") -> Temps (en s) | B3: =INDIRECT(ADDRESS($B2+1,COLUMN(B3))) -> 0 | C3: =INDIRECT(ADDRESS($B2+1,COLUMN(C3))) -> 0.05 | D3: =INDIRECT(ADDRESS($B2+1,COLUMN(D3))) -> 0.5 | E3: =INDIRECT(ADDRESS($B2+1,COLUMN(E3))) -> 1 | F3: =INDIRECT(ADDRESS($B2+1,COLUMN(F3))) -> 1.5 | G3: =INDIRECT(ADDRESS($B2+1,COLUMN(G3))) -> 2 | H3: =INDIRECT(ADDRESS($B2+1,COLUMN(H3))) -> 2.5 | I3: =INDIRECT(ADDRESS($B2+1,COLUMN(I3))) -> 2.97 | ... Y3: =INDIRECT(ADDRESS($B2+1,COLUMN(Y3))) -> 1000
A4: =IF(Lang="Français","Poussée (en N)","Thrust (N)") -> Poussée (en N) | B4: =INDIRECT(ADDRESS($B2+2,COLUMN(B3))) -> 0 | C4: =INDIRECT(ADDRESS($B2+2,COLUMN(C3))) -> 893 | D4: =INDIRECT(ADDRESS($B2+2,COLUMN(D3))) -> 798 | E4: =INDIRECT(ADDRESS($B2+2,COLUMN(E3))) -> 739 | F4: =INDIRECT(ADDRESS($B2+2,COLUMN(F3))) -> 659 | G4: =INDIRECT(ADDRESS($B2+2,COLUMN(G3))) -> 586 | H4: =INDIRECT(ADDRESS($B2+2,COLUMN(H3))) -> 513 | I4: =INDIRECT(ADDRESS($B2+2,COLUMN(I3))) -> 417 | ... Y4: =INDIRECT(ADDRESS($B2+2,COLUMN(Y3))) -> 0
A25: H2O
A26: H2O 1.5L 300g 6bar | B26: =ROW(A26) -> 26 | C26: I_total | D26: =SUM(B29:Y29) -> 9.845 | E26: ISP | F26: =D26/g/J26 -> 3.345226 | G26: MpropuPlein | H26: 0.3 | I26: M_éjecté | J26: =H26-L26 -> 0.3 | K26: M_burnout | L26: 0 | M26: XpropuPlein | N26: =0.2*R26 -> 60 | O26: XpropuVide | P26: 150 | Q26: Longueur | R26: 300 | S26: Diamètre | T26: 90 | U26: Type | V26: H2O
A27: Temps (en s) | B27: 0 | C27: 0.001 | D27: 0.02 | E27: 0.038 | F27: 0.04 | G27: 0.04 | H27: 0.04 | I27: 0.04 | J27: 0.04 | K27: 0.04 | L27: 0.04 | M27: 0.04 | N27: 0.04 | O27: 0.04 | P27: 0.04 | Q27: 0.04 | R27: 0.04 | S27: 0.04 | T27: 0.04 | U27: 0.04 | V27: 0.04 | W27: 0.04 | X27: 0.04 | Y27: 1000
A28: Poussée (en N) | B28: 0 | C28: 310 | D28: 250 | E28: 212 | F28: 0 | G28: 0 | H28: 0 | I28: 0 | J28: 0 | K28: 0 | L28: 0 | M28: 0 | N28: 0 | O28: 0 | P28: 0 | Q28: 0 | R28: 0 | S28: 0 | T28: 0 | U28: 0 | V28: 0 | W28: 0 | X28: 0 | Y28: 0
A29: I_total_i (en N.s) | B29: =(C28+B28)*(C27-B27)/2 -> 0.155 | C29: =(D28+C28)*(D27-C27)/2 -> 5.32 | D29: =(E28+D28)*(E27-D27)/2 -> 4.158 | E29: =(F28+E28)*(F27-E27)/2 -> 0.212 | F29: =(G28+F28)*(G27-F27)/2 -> 0 | G29: =(H28+G28)*(H27-G27)/2 -> 0 | H29: =(I28+H28)*(I27-H27)/2 -> 0 | I29: =(J28+I28)*(J27-I27)/2 -> 0 | ... X29: =(Y28+X28)*(Y27-X27)/2 -> 0
A31: H2O 1.5L 450g 6bar | B31: =ROW(A31) -> 31 | C31: I_total | D31: =SUM(B34:Y34) -> 13.8145 | E31: ISP | F31: =D31/g/J31 -> 3.1293465 | G31: MpropuPlein | H31: 0.45 | I31: M_éjecté | J31: =H31-L31 -> 0.45 | K31: M_burnout | L31: 0 | M31: XpropuPlein | N31: =0.3*R31 -> 90 | O31: XpropuVide | P31: 150 | Q31: Longueur | R31: 300 | S31: Diamètre | T31: 90 | U31: Type | V31: H2O
A32: Temps (en s) | B32: 0 | C32: 0.001 | D32: 0.02 | E32: 0.04 | F32: 0.061 | G32: 0.062 | H32: 0.062 | I32: 0.062 | J32: 0.062 | K32: 0.062 | L32: 0.062 | M32: 0.062 | N32: 0.062 | O32: 0.062 | P32: 0.062 | Q32: 0.062 | R32: 0.062 | S32: 0.062 | T32: 0.062 | U32: 0.062 | V32: 0.062 | W32: 0.062 | X32: 0.062 | Y32: 1000
A33: Poussée (en N) | B33: 0 | C33: 310 | D33: 245 | E33: 200 | F33: 167 | G33: 0 | H33: 0 | I33: 0 | J33: 0 | K33: 0 | L33: 0 | M33: 0 | N33: 0 | O33: 0 | P33: 0 | Q33: 0 | R33: 0 | S33: 0 | T33: 0 | U33: 0 | V33: 0 | W33: 0 | X33: 0 | Y33: 0
A34: I_total_i (en N.s) | B34: =(C33+B33)*(C32-B32)/2 -> 0.155 | C34: =(D33+C33)*(D32-C32)/2 -> 5.2725 | D34: =(E33+D33)*(E32-D32)/2 -> 4.45 | E34: =(F33+E33)*(F32-E32)/2 -> 3.8535 | F34: =(G33+F33)*(G32-F32)/2 -> 0.0835 | G34: =(H33+G33)*(H32-G32)/2 -> 0 | H34: =(I33+H33)*(I32-H32)/2 -> 0 | I34: =(J33+I33)*(J32-I32)/2 -> 0 | ... X34: =(Y33+X33)*(Y32-X32)/2 -> 0
A36: H2O 1.5L 600g 6bar | B36: =ROW(A36) -> 36 | C36: I_total | D36: =SUM(B39:Y39) -> 17.1445 | E36: ISP | F36: =D36/g/J36 -> 2.9127591 | G36: MpropuPlein | H36: 0.6 | I36: M_éjecté | J36: =H36-L36 -> 0.6 | K36: M_burnout | L36: 0 | M36: XpropuPlein | N36: =0.4*R36 -> 120 | O36: XpropuVide | P36: 150 | Q36: Longueur | R36: 300 | S36: Diamètre | T36: 90 | U36: Type | V36: H2O
A37: Temps (en s) | B37: 0 | C37: 0.001 | D37: 0.02 | E37: 0.04 | F37: 0.06 | G37: 0.08 | H37: 0.088 | I37: 0.089 | J37: 0.089 | K37: 0.089 | L37: 0.089 | M37: 0.089 | N37: 0.089 | O37: 0.089 | P37: 0.089 | Q37: 0.089 | R37: 0.089 | S37: 0.089 | T37: 0.089 | U37: 0.089 | V37: 0.089 | W37: 0.089 | X37: 0.089 | Y37: 1000
A38: Poussée (en N) | B38: 0 | C38: 310 | D38: 240 | E38: 190 | F38: 157 | G38: 133 | H38: 125 | I38: 0 | J38: 0 | K38: 0 | L38: 0 | M38: 0 | N38: 0 | O38: 0 | P38: 0 | Q38: 0 | R38: 0 | S38: 0 | T38: 0 | U38: 0 | V38: 0 | W38: 0 | X38: 0 | Y38: 0
A39: I_total_i (en N.s) | B39: =(C38+B38)*(C37-B37)/2 -> 0.155 | C39: =(D38+C38)*(D37-C37)/2 -> 5.225 | D39: =(E38+D38)*(E37-D37)/2 -> 4.3 | E39: =(F38+E38)*(F37-E37)/2 -> 3.47 | F39: =(G38+F38)*(G37-F37)/2 -> 2.9 | G39: =(H38+G38)*(H37-G37)/2 -> 1.032 | H39: =(I38+H38)*(I37-H37)/2 -> 0.0625 | I39: =(J38+I38)*(J37-I37)/2 -> 0 | ... X39: =(Y38+X38)*(Y37-X37)/2 -> 0
A41: H2O 1.5L 750g 6bar | B41: =ROW(A41) -> 41 | C41: I_total | D41: =SUM(B44:Y44) -> 19.415 | E41: ISP | F41: =D41/g/J41 -> 2.6388039 | G41: MpropuPlein | H41: 0.75 | I41: M_éjecté | J41: =H41-L41 -> 0.75 | K41: M_burnout | L41: 0 | M41: XpropuPlein | N41: =0.5*R41 -> 150 | O41: XpropuVide | P41: 150 | Q41: Longueur | R41: 300 | S41: Diamètre | T41: 90 | U41: Type | V41: H2O
A42: Temps (en s) | B42: 0 | C42: 0.001 | D42: 0.02 | E42: 0.04 | F42: 0.06 | G42: 0.08 | H42: 0.1 | I42: 0.123 | J42: 0.124 | K42: 0.124 | L42: 0.124 | M42: 0.124 | N42: 0.124 | O42: 0.124 | P42: 0.124 | Q42: 0.124 | R42: 0.124 | S42: 0.124 | T42: 0.124 | U42: 0.124 | V42: 0.124 | W42: 0.124 | X42: 0.124 | Y42: 1000
A43: Poussée (en N) | B43: 0 | C43: 310 | D43: 230 | E43: 175 | F43: 140 | G43: 118 | H43: 100 | I43: 85 | J43: 0 | K43: 0 | L43: 0 | M43: 0 | N43: 0 | O43: 0 | P43: 0 | Q43: 0 | R43: 0 | S43: 0 | T43: 0 | U43: 0 | V43: 0 | W43: 0 | X43: 0 | Y43: 0
A44: I_total_i (en N.s) | B44: =(C43+B43)*(C42-B42)/2 -> 0.155 | C44: =(D43+C43)*(D42-C42)/2 -> 5.13 | D44: =(E43+D43)*(E42-D42)/2 -> 4.05 | E44: =(F43+E43)*(F42-E42)/2 -> 3.15 | F44: =(G43+F43)*(G42-F42)/2 -> 2.58 | G44: =(H43+G43)*(H42-G42)/2 -> 2.18 | H44: =(I43+H43)*(I42-H42)/2 -> 2.1275 | I44: =(J43+I43)*(J42-I42)/2 -> 0.0425 | ... X44: =(Y43+X43)*(Y42-X42)/2 -> 0
A46: H2O 2.0L 400g 6bar | B46: =ROW(A46) -> 46 | C46: I_total | D46: =SUM(B49:Y49) -> 12.8695 | E46: ISP | F46: =D46/g/J46 -> 3.2796891 | G46: MpropuPlein | H46: 0.5 | I46: M_éjecté | J46: =H46-L46 -> 0.4 | K46: M_burnout | L46: 0.1 | M46: XpropuPlein | N46: =0.2*R46 -> 60 | O46: XpropuVide | P46: 150 | Q46: Longueur | R46: 300 | S46: Diamètre | T46: 98 | U46: Type | V46: H2O
A47: Temps (en s) | B47: 0 | C47: 0.001 | D47: 0.02 | E47: 0.04 | F47: 0.05 | G47: 0.051 | H47: 0.051 | I47: 0.051 | J47: 0.051 | K47: 0.051 | L47: 0.051 | M47: 0.051 | N47: 0.051 | O47: 0.051 | P47: 0.051 | Q47: 0.051 | R47: 0.051 | S47: 0.051 | T47: 0.051 | U47: 0.051 | V47: 0.051 | W47: 0.051 | X47: 0.051 | Y47: 1000
A48: Poussée (en N) | B48: 0 | C48: 310 | D48: 264 | E48: 230 | F48: 213 | G48: 0 | H48: 0 | I48: 0 | J48: 0 | K48: 0 | L48: 0 | M48: 0 | N48: 0 | O48: 0 | P48: 0 | Q48: 0 | R48: 0 | S48: 0 | T48: 0 | U48: 0 | V48: 0 | W48: 0 | X48: 0 | Y48: 0
A49: I_total_i (en N.s) | B49: =(C48+B48)*(C47-B47)/2 -> 0.155 | C49: =(D48+C48)*(D47-C47)/2 -> 5.453 | D49: =(E48+D48)*(E47-D47)/2 -> 4.94 | E49: =(F48+E48)*(F47-E47)/2 -> 2.215 | F49: =(G48+F48)*(G47-F47)/2 -> 0.1065 | G49: =(H48+G48)*(H47-G47)/2 -> 0 | H49: =(I48+H48)*(I47-H47)/2 -> 0 | I49: =(J48+I48)*(J47-I47)/2 -> 0 | ... X49: =(Y48+X48)*(Y47-X47)/2 -> 0
A51: H2O 2.0L 600g 6bar | B51: =ROW(A51) -> 51 | C51: I_total | D51: =SUM(B54:Y54) -> 18.1235 | E51: ISP | F51: =D51/g/J51 -> 3.079086 | G51: MpropuPlein | H51: 0.7 | I51: M_éjecté | J51: =H51-L51 -> 0.6 | K51: M_burnout | L51: 0.1 | M51: XpropuPlein | N51: =0.3*R51 -> 90 | O51: XpropuVide | P51: 150 | Q51: Longueur | R51: 300 | S51: Diamètre | T51: 98 | U51: Type | V51: H2O
A52: Temps (en s) | B52: 0 | C52: 0.001 | D52: 0.02 | E52: 0.04 | F52: 0.06 | G52: 0.08 | H52: 0.081 | I52: 0.081 | J52: 0.081 | K52: 0.081 | L52: 0.081 | M52: 0.081 | N52: 0.081 | O52: 0.081 | P52: 0.081 | Q52: 0.081 | R52: 0.081 | S52: 0.081 | T52: 0.081 | U52: 0.081 | V52: 0.081 | W52: 0.081 | X52: 0.081 | Y52: 1000
A53: Poussée (en N) | B53: 0 | C53: 310 | D53: 260 | E53: 220 | F53: 190 | G53: 167 | H53: 0 | I53: 0 | J53: 0 | K53: 0 | L53: 0 | M53: 0 | N53: 0 | O53: 0 | P53: 0 | Q53: 0 | R53: 0 | S53: 0 | T53: 0 | U53: 0 | V53: 0 | W53: 0 | X53: 0 | Y53: 0
A54: I_total_i (en N.s) | B54: =(C53+B53)*(C52-B52)/2 -> 0.155 | C54: =(D53+C53)*(D52-C52)/2 -> 5.415 | D54: =(E53+D53)*(E52-D52)/2 -> 4.8 | E54: =(F53+E53)*(F52-E52)/2 -> 4.1 | F54: =(G53+F53)*(G52-F52)/2 -> 3.57 | G54: =(H53+G53)*(H52-G52)/2 -> 0.0835 | H54: =(I53+H53)*(I52-H52)/2 -> 0 | I54: =(J53+I53)*(J52-I52)/2 -> 0 | ... X54: =(Y53+X53)*(Y52-X52)/2 -> 0
A56: H2O 2.0L 800g 6bar | B56: =ROW(A56) -> 56 | C56: I_total | D56: =SUM(B59:Y59) -> 22.61 | E56: ISP | F56: =D56/g/J56 -> 2.8809888 | G56: MpropuPlein | H56: 0.9 | I56: M_éjecté | J56: =H56-L56 -> 0.8 | K56: M_burnout | L56: 0.1 | M56: XpropuPlein | N56: =0.4*R56 -> 120 | O56: XpropuVide | P56: 150 | Q56: Longueur | R56: 300 | S56: Diamètre | T56: 98 | U56: Type | V56: H2O
A57: Temps (en s) | B57: 0 | C57: 0.001 | D57: 0.02 | E57: 0.04 | F57: 0.06 | G57: 0.08 | H57: 0.1 | I57: 0.117 | J57: 0.118 | K57: 0.118 | L57: 0.118 | M57: 0.118 | N57: 0.118 | O57: 0.118 | P57: 0.118 | Q57: 0.118 | R57: 0.118 | S57: 0.118 | T57: 0.118 | U57: 0.118 | V57: 0.118 | W57: 0.118 | X57: 0.118 | Y57: 1000
A58: Poussée (en N) | B58: 0 | C58: 310 | D58: 250 | E58: 210 | F58: 180 | G58: 156 | H58: 140 | I58: 125 | J58: 0 | K58: 0 | L58: 0 | M58: 0 | N58: 0 | O58: 0 | P58: 0 | Q58: 0 | R58: 0 | S58: 0 | T58: 0 | U58: 0 | V58: 0 | W58: 0 | X58: 0 | Y58: 0
A59: I_total_i (en N.s) | B59: =(C58+B58)*(C57-B57)/2 -> 0.155 | C59: =(D58+C58)*(D57-C57)/2 -> 5.32 | D59: =(E58+D58)*(E57-D57)/2 -> 4.6 | E59: =(F58+E58)*(F57-E57)/2 -> 3.9 | F59: =(G58+F58)*(G57-F57)/2 -> 3.36 | G59: =(H58+G58)*(H57-G57)/2 -> 2.96 | H59: =(I58+H58)*(I57-H57)/2 -> 2.2525 | I59: =(J58+I58)*(J57-I57)/2 -> 0.0625 | ... X59: =(Y58+X58)*(Y57-X57)/2 -> 0
A61: H2O 2.0L 1000g 6bar | B61: =ROW(A61) -> 61 | C61: I_total | D61: =SUM(B64:Y64) -> 25.874 | E61: ISP | F61: =D61/g/J61 -> 2.6375127 | G61: MpropuPlein | H61: 1.1 | I61: M_éjecté | J61: =H61-L61 -> 1 | K61: M_burnout | L61: 0.1 | M61: XpropuPlein | N61: =0.5*R61 -> 150 | O61: XpropuVide | P61: 150 | Q61: Longueur | R61: 300 | S61: Diamètre | T61: 98 | U61: Type | V61: H2O
A62: Temps (en s) | B62: 0 | C62: 0.001 | D62: 0.02 | E62: 0.04 | F62: 0.06 | G62: 0.08 | H62: 0.1 | I62: 0.12 | J62: 0.14 | K62: 0.164 | L62: 0.165 | M62: 0.165 | N62: 0.165 | O62: 0.165 | P62: 0.165 | Q62: 0.165 | R62: 0.165 | S62: 0.165 | T62: 0.165 | U62: 0.165 | V62: 0.165 | W62: 0.165 | X62: 0.165 | Y62: 1000
A63: Poussée (en N) | B63: 0 | C63: 310 | D63: 245 | E63: 200 | F63: 165 | G63: 143 | H63: 124 | I63: 108 | J63: 97 | K63: 85 | L63: 0 | M63: 0 | N63: 0 | O63: 0 | P63: 0 | Q63: 0 | R63: 0 | S63: 0 | T63: 0 | U63: 0 | V63: 0 | W63: 0 | X63: 0 | Y63: 0
A64: I_total_i (en N.s) | B64: =(C63+B63)*(C62-B62)/2 -> 0.155 | C64: =(D63+C63)*(D62-C62)/2 -> 5.2725 | D64: =(E63+D63)*(E62-D62)/2 -> 4.45 | E64: =(F63+E63)*(F62-E62)/2 -> 3.65 | F64: =(G63+F63)*(G62-F62)/2 -> 3.08 | G64: =(H63+G63)*(H62-G62)/2 -> 2.67 | H64: =(I63+H63)*(I62-H62)/2 -> 2.32 | I64: =(J63+I63)*(J62-I62)/2 -> 2.05 | ... X64: =(Y63+X63)*(Y62-X62)/2 -> 0
A66: µ-propu
A67: µ-propu A8-3 | B67: =ROW(A67) -> 67 | C67: I_total | D67: =SUM(B70:Y70) -> 2.65 | E67: ISP | F67: =D67/g/J67 -> 54.026504 | G67: MpropuPlein | H67: 0.015 | I67: M_éjecté | J67: =H67-L67 -> 0.005 | K67: M_burnout | L67: 0.01 | M67: XpropuPlein | N67: 30 | O67: XpropuVide | P67: 30 | Q67: Longueur | R67: 70 | S67: Diamètre | T67: 15 | U67: Type | V67: Micro | W67: Combustion | X67: 0.32 | Y67: Dépotage | Z67: 3
A68: Temps (en s) | B68: 0 | C68: 0.2 | D68: 0.3 | E68: 0.4 | F68: 0.5 | G68: 0.55 | H68: 0.6 | I68: 0.6 | J68: 0.6 | K68: 0.6 | L68: 0.6 | M68: 0.6 | N68: 0.6 | O68: 0.6 | P68: 0.6 | Q68: 0.6 | R68: 0.6 | S68: 0.6 | T68: 0.6 | U68: 0.6 | V68: 0.6 | W68: 0.6 | X68: 0.6 | Y68: 1000
...

Sheet Calculs
D1: Dynamique de la fusée (repère sol) | P1: Forces | AC1: Sous-échantillon 1Hz | AG1: Accélération longitudinale
A2: pas | B2: t | D2: acc_x | E2: acc_z | F2: acc_xz | G2: vit_x | H2: vit_z | I2: vit_xz | J2: pos_x | K2: pos_z | L2: pos_xz | M2: Beta | N2: BetaD | P2: i_P | Q2: Poussée | R2: Débit | S2: m | T2: Poids | U2: R_rampe | V2: Rho | W2: Trainée | Y2: Événements | AC2: Temps | AD2: x | AE2: z | AG2: gravitationnelle | AH2: non-gravit.
A3: s | B3: s | D3: m/s² | E3: m/s² | F3: m/s² | G3: m/s | H3: m/s | I3: m/s | J3: m | K3: m | L3: m | M3: rad | N3: ° | P3: - | Q3: N | R3: kg/s | S3: kg | T3: N | U3: N | V3: kg/m3 | W3: N | AC3: s | AD3: m | AE3: m | AG3: m/s² | AH3: m/s²
A4: - | B4: =T_ini -> 3.7 | D4: - | E4: - | F4: - | G4: =vit_xz*COS(Beta) -> 21.687707 | H4: =vit_xz*SIN(Beta) -> 69.383784 | I4: =V_ini -> 72.694334 | J4: =X_ini -> 86.435214 | K4: =Z_ini -> 353.9867 | L4: =SQRT(pos_x^2+pos_z^2) -> 364.38665 | M4: =RADIANS(N4) -> 1.2678422 | N4: =Beta_rampe -> 72.642008 | P4: - | Q4: - | R4: - | S4: =m_tot -> 9.485 | T4: =m*g -> 93.04785 | U4: =IF(pos_xz<L_rampe,Poids*COS(Beta),0) -> 0 | V4: =Rho_moyen*(20000-Alt_rampe-pos_z)/(20000+Alt_rampe+pos_z) -> 1.1823908 | W4: =1/2*Rho*Sref*Cx*vit_xz^2 -> 13.687103 | Y4: - | Z4: - | AA4: - | AC4: =IF(ABS(t-ROUND(t,0))<0.001,t,-1) -> -1 | AD4: =IF(ABS(t-ROUND(t,0))<0.001,pos_x,-1) -> -1 | AE4: =IF(t<T_para, pos_z, NA()) -> 353.9867 | AG4: - | AH4: -
A5: =IF(B4+0.01<=T_ini+ROUNDUP(Temps_fin_propu,0), 0.01, IF(K4>0, 0.1, 0.0001)) -> 0.01 | B5: =B4+pas -> 3.71 | D5: =IF(AND(L4<L_rampe,Poussee<Poids*SIN(M4)),0,(-W4+Poussee)/m*COS(M4)-U4/m*SIN(M4)) -> 2.3784397 | E5: =IF(AND(L4<L_rampe,Poussee<Poids*SIN(M4)),0,(-W4+Poussee)/m*SIN(M4)+U4/m*COS(M4)-Poids/m) -> -2.200844 | F5: =SQRT(acc_x^2+acc_z^2) -> 3.2404767 | G5: =G4+acc_x*pas -> 21.711491 | H5: =H4+acc_z*pas -> 69.361776 | I5: =SQRT(vit_x^2+vit_z^2) -> 72.680429 | J5: =J4+0.5*(vit_x+G4)*pas*(K4>=0) -> 86.65221 | K5: =K4+0.5*(vit_z+H4)*pas -> 354.68043 | L5: =SQRT(pos_x^2+pos_z^2) -> 365.11205 | M5: =IF(AND(L4>L_rampe,G5>0),ATAN2(G5,H5),$M$4) -> 1.2674395 | N5: =DEGREES(Beta) -> 72.618936 | P5: =MATCH(t-pas/2-T_ini,CdP_t) -> 1 | Q5: =(INDEX(CdP,2,i_P+1)-INDEX(CdP,2,i_P+0))/(INDEX(CdP,1,i_P+1)-INDEX(CdP,1,i_P+0))*(t-pas/2-T_ini-INDEX(CdP,1,i_P+0))+INDEX(CdP,2,i_P+0) -> 89.3 | R5: =Poussee/(g*ISP) -> 0.044815509 | S5: =S4-Débit*pas -> 9.4845518 | T5: =m*g -> 93.043454 | U5: =IF(pos_xz<L_rampe,Poids*COS(Beta),0) -> 0 | V5: =Rho_moyen*(20000-Alt_rampe-pos_z)/(20000+Alt_rampe+pos_z) -> 1.1823087 | W5: =1/2*Rho*Sref*Cx*vit_xz^2 -> 13.680918 | Y5: =IF(AND(pos_z<=0,K4>0),"Impact balistique","") & IF(AND(H6<0,vit_z>=0),"Apogée","") & IF(AND(Poussee=0,Q4>0),"Fin de propulsion","") & IF(AND(L6>L_rampe,pos_xz<=L_rampe),"Sortie de rampe","") | Z5: =IF(ABS(t-T_para)<pas/2,"Para","") | AA5: =IF(ABS(t-T_satellite)<pas/2,"Satellite","") | AC5: =IF(ABS(t-ROUND(t,0))<0.001,t,NA()) -> #N/A | AD5: =IF(ABS(t-ROUND(t,0))<0.001,pos_x,NA()) -> #N/A | AE5: =IF(t<T_para, pos_z, NA()) -> 354.68043 | AG5: =IF(AND(L4<L_rampe,Poussee<Poids*SIN(M4)),0,(-W4+Poussee)/m-Poids*SIN(M4)/m) -> -1.3910298 | AH5: =IF(AND(L4<L_rampe,Poussee<Poids*SIN(M4)), g*SIN(M4), (-W4+Poussee)/m) -> 7.9722161
A6: =IF(B5+0.01<=T_ini+ROUNDUP(Temps_fin_propu,0), 0.01, IF(K5>0, 0.1, 0.0001)) -> 0.01 | B6: =B5+pas -> 3.72 | D6: =IF(AND(L5<L_rampe,Poussee<Poids*SIN(M5)),0,(-W5+Poussee)/m*COS(M5)-U5/m*SIN(M5)) -> 8.0080185 | E6: =IF(AND(L5<L_rampe,Poussee<Poids*SIN(M5)),0,(-W5+Poussee)/m*SIN(M5)+U5/m*COS(M5)-Poids/m) -> 15.773244 | F6: =SQRT(acc_x^2+acc_z^2) -> 17.689647 | G6: =G5+acc_x*pas -> 21.791571 | H6: =H5+acc_z*pas -> 69.519508 | I6: =SQRT(vit_x^2+vit_z^2) -> 72.854887 | J6: =J5+0.5*(vit_x+G5)*pas*(K5>=0) -> 86.869726 | K6: =K5+0.5*(vit_z+H5)*pas -> 355.37483 | L6: =SQRT(pos_x^2+pos_z^2) -> 365.83825 | M6: =IF(AND(L5>L_rampe,G6>0),ATAN2(G6,H6),$M$4) -> 1.2670373 | N6: =DEGREES(Beta) -> 72.595889 | P6: =MATCH(t-pas/2-T_ini,CdP_t) -> 1 | Q6: =(INDEX(CdP,2,i_P+1)-INDEX(CdP,2,i_P+0))/(INDEX(CdP,1,i_P+1)-INDEX(CdP,1,i_P+0))*(t-pas/2-T_ini-INDEX(CdP,1,i_P+0))+INDEX(CdP,2,i_P+0) -> 267.9 | R6: =Poussee/(g*ISP) -> 0.13444653 | S6: =S5-Débit*pas -> 9.4832074 | T6: =m*g -> 93.030264 | U6: =IF(pos_xz<L_rampe,Poids*COS(Beta),0) -> 0 | V6: =Rho_moyen*(20000-Alt_rampe-pos_z)/(20000+Alt_rampe+pos_z) -> 1.1822266 | W6: =1/2*Rho*Sref*Cx*vit_xz^2 -> 13.74572 | Y6: =IF(AND(pos_z<=0,K5>0),"Impact balistique","") & IF(AND(H7<0,vit_z>=0),"Apogée","") & IF(AND(Poussee=0,Q5>0),"Fin de propulsion","") & IF(AND(L7>L_rampe,pos_xz<=L_rampe),"Sortie de rampe","") | Z6: =IF(ABS(t-T_para)<pas/2,"Para","") | AA6: =IF(ABS(t-T_satellite)<pas/2,"Satellite","") | AC6: =IF(ABS(t-ROUND(t,0))<0.001,t,NA()) -> #N/A | AD6: =IF(ABS(t-ROUND(t,0))<0.001,pos_x,NA()) -> #N/A | AE6: =IF(t<T_para, pos_z, NA()) -> 355.37483 | AG6: =IF(AND(L5<L_rampe,Poussee<Poids*SIN(M5)),0,(-W5+Poussee)/m-Poids*SIN(M5)/m) -> 17.445223 | AH6: =IF(AND(L5<L_rampe,Poussee<Poids*SIN(M5)), g*SIN(M5), (-W5+Poussee)/m) -> 26.807289
A7: =IF(B6+0.01<=T_ini+ROUNDUP(Temps_fin_propu,0), 0.01, IF(K6>0, 0.1, 0.0001)) -> 0.01 | B7: =B6+pas -> 3.73 | D7: =IF(AND(L6<L_rampe,Poussee<Poids*SIN(M6)),0,(-W6+Poussee)/m*COS(M6)-U6/m*SIN(M6)) -> 13.652702 | E7: =IF(AND(L6<L_rampe,Poussee<Poids*SIN(M6)),0,(-W6+Poussee)/m*SIN(M6)+U6/m*COS(M6)-Poids/m) -> 33.744873 | F7: =SQRT(acc_x^2+acc_z^2) -> 36.402098 | G7: =G6+acc_x*pas -> 21.928098 | H7: =H6+acc_z*pas -> 69.856957 | I7: =SQRT(vit_x^2+vit_z^2) -> 73.21773 | J7: =J6+0.5*(vit_x+G6)*pas*(K6>=0) -> 87.088324 | K7: =K6+0.5*(vit_z+H6)*pas -> 356.07172 | L7: =SQRT(pos_x^2+pos_z^2) -> 366.56711 | M7: =IF(AND(L6>L_rampe,G7>0),ATAN2(G7,H7),$M$4) -> 1.2666365 | N7: =DEGREES(Beta) -> 72.572927 | P7: =MATCH(t-pas/2-T_ini,CdP_t) -> 1 | Q7: =(INDEX(CdP,2,i_P+1)-INDEX(CdP,2,i_P+0))/(INDEX(CdP,1,i_P+1)-INDEX(CdP,1,i_P+0))*(t-pas/2-T_ini-INDEX(CdP,1,i_P+0))+INDEX(CdP,2,i_P+0) -> 446.5 | R7: =Poussee/(g*ISP) -> 0.22407755 | S7: =S6-Débit*pas -> 9.4809666 | T7: =m*g -> 93.008282 | U7: =IF(pos_xz<L_rampe,Poids*COS(Beta),0) -> 0 | V7: =Rho_moyen*(20000-Alt_rampe-pos_z)/(20000+Alt_rampe+pos_z) -> 1.1821442 | W7: =1/2*Rho*Sref*Cx*vit_xz^2 -> 13.88201 | Y7: =IF(AND(pos_z<=0,K6>0),"Impact balistique","") & IF(AND(H8<0,vit_z>=0),"Apogée","") & IF(AND(Poussee=0,Q6>0),"Fin de propulsion","") & IF(AND(L8>L_rampe,pos_xz<=L_rampe),"Sortie de rampe","") | Z7: =IF(ABS(t-T_para)<pas/2,"Para","") | AA7: =IF(ABS(t-T_satellite)<pas/2,"Satellite","") | AC7: =IF(ABS(t-ROUND(t,0))<0.001,t,NA()) -> #N/A | AD7: =IF(ABS(t-ROUND(t,0))<0.001,pos_x,NA()) -> #N/A | AE7: =IF(t<T_para, pos_z, NA()) -> 356.07172 | AG7: =IF(AND(L6<L_rampe,Poussee<Poids*SIN(M6)),0,(-W6+Poussee)/m-Poids*SIN(M6)/m) -> 36.283645 | AH7: =IF(AND(L6<L_rampe,Poussee<Poids*SIN(M6)), g*SIN(M6), (-W6+Poussee)/m) -> 45.644532
A8: =IF(B7+0.01<=T_ini+ROUNDUP(Temps_fin_propu,0), 0.01, IF(K7>0, 0.1, 0.0001)) -> 0.01 | B8: =B7+pas -> 3.74 | D8: =IF(AND(L7<L_rampe,Poussee<Poids*SIN(M7)),0,(-W7+Poussee)/m*COS(M7)-U7/m*SIN(M7)) -> 19.313988 | E8: =IF(AND(L7<L_rampe,Poussee<Poids*SIN(M7)),0,(-W7+Poussee)/m*SIN(M7)+U7/m*COS(M7)-Poids/m) -> 51.719111 | F8: =SQRT(acc_x^2+acc_z^2) -> 55.207758 | G8: =G7+acc_x*pas -> 22.121238 | H8: =H7+acc_z*pas -> 70.374148 | I8: =SQRT(vit_x^2+vit_z^2) -> 73.769031 | J8: =J7+0.5*(vit_x+G7)*pas*(K7>=0) -> 87.308571 | K8: =K7+0.5*(vit_z+H7)*pas -> 356.77287 | L8: =SQRT(pos_x^2+pos_z^2) -> 367.30052 | M8: =IF(AND(L7>L_rampe,G8>0),ATAN2(G8,H8),$M$4) -> 1.2662383 | N8: =DEGREES(Beta) -> 72.550108 | P8: =MATCH(t-pas/2-T_ini,CdP_t) -> 1 | Q8: =(INDEX(CdP,2,i_P+1)-INDEX(CdP,2,i_P+0))/(INDEX(CdP,1,i_P+1)-INDEX(CdP,1,i_P+0))*(t-pas/2-T_ini-INDEX(CdP,1,i_P+0))+INDEX(CdP,2,i_P+0) -> 625.1 | R8: =Poussee/(g*ISP) -> 0.31370857 | S8: =S7-Débit*pas -> 9.4778295 | T8: =m*g -> 92.977508 | U8: =IF(pos_xz<L_rampe,Poids*COS(Beta),0) -> 0 | V8: =Rho_moyen*(20000-Alt_rampe-pos_z)/(20000+Alt_rampe+pos_z) -> 1.1820613 | W8: =1/2*Rho*Sref*Cx*vit_xz^2 -> 14.090861 | Y8: =IF(AND(pos_z<=0,K7>0),"Impact balistique","") & IF(AND(H9<0,vit_z>=0),"Apogée","") & IF(AND(Poussee=0,Q7>0),"Fin de propulsion","") & IF(AND(L9>L_rampe,pos_xz<=L_rampe),"Sortie de rampe","") | Z8: =IF(ABS(t-T_para)<pas/2,"Para","") | AA8: =IF(ABS(t-T_satellite)<pas/2,"Satellite","") | AC8: =IF(ABS(t-ROUND(t,0))<0.001,t,NA()) -> #N/A | AD8: =IF(ABS(t-ROUND(t,0))<0.001,pos_x,NA()) -> #N/A | AE8: =IF(t<T_para, pos_z, NA()) -> 356.77287 | AG8: =IF(AND(L7<L_rampe,Poussee<Poids*SIN(M7)),0,(-W7+Poussee)/m-Poids*SIN(M7)/m) -> 55.129526 | AH8: =IF(AND(L7<L_rampe,Poussee<Poids*SIN(M7)), g*SIN(M7), (-W7+Poussee)/m) -> 64.489237
A9: =IF(B8+0.01<=T_ini+ROUNDUP(Temps_fin_propu,0), 0.01, IF(K8>0, 0.1, 0.0001)) -> 0.01 | B9: =B8+pas -> 3.75 | D9: =IF(AND(L8<L_rampe,Poussee<Poids*SIN(M8)),0,(-W8+Poussee)/m*COS(M8)-U8/m*SIN(M8)) -> 24.993293 | E9: =IF(AND(L8<L_rampe,Poussee<Poids*SIN(M8)),0,(-W8+Poussee)/m*SIN(M8)+U8/m*COS(M8)-Poids/m) -> 69.700998 | F9: =SQRT(acc_x^2+acc_z^2) -> 74.046565 | G9: =G8+acc_x*pas -> 22.371171 | H9: =H8+acc_z*pas -> 71.071158 | I9: =SQRT(vit_x^2+vit_z^2) -> 74.508918 | J9: =J8+0.5*(vit_x+G8)*pas*(K8>=0) -> 87.531033 | K9: =K8+0.5*(vit_z+H8)*pas -> 357.4801 | L9: =SQRT(pos_x^2+pos_z^2) -> 368.04035 | M9: =IF(AND(L8>L_rampe,G9>0),ATAN2(G9,H9),$M$4) -> 1.2658434 | N9: =DEGREES(Beta) -> 72.527487 | P9: =MATCH(t-pas/2-T_ini,CdP_t) -> 1 | Q9: =(INDEX(CdP,2,i_P+1)-INDEX(CdP,2,i_P+0))/(INDEX(CdP,1,i_P+1)-INDEX(CdP,1,i_P+0))*(t-pas/2-T_ini-INDEX(CdP,1,i_P+0))+INDEX(CdP,2,i_P+0) -> 803.7 | R9: =Poussee/(g*ISP) -> 0.40333958 | S9: =S8-Débit*pas -> 9.4737961 | T9: =m*g -> 92.93794 | U9: =IF(pos_xz<L_rampe,Poids*COS(Beta),0) -> 0 | V9: =Rho_moyen*(20000-Alt_rampe-pos_z)/(20000+Alt_rampe+pos_z) -> 1.1819777 | W9: =1/2*Rho*Sref*Cx*vit_xz^2 -> 14.373918 | Y9: =IF(AND(pos_z<=0,K8>0),"Impact balistique","") & IF(AND(H10<0,vit_z>=0),"Apogée","") & IF(AND(Poussee=0,Q8>0),"Fin de propulsion","") & IF(AND(L10>L_rampe,pos_xz<=L_rampe),"Sortie de rampe","") | Z9: =IF(ABS(t-T_para)<pas/2,"Para","") | AA9: =IF(ABS(t-T_satellite)<pas/2,"Satellite","") | AC9: =IF(ABS(t-ROUND(t,0))<0.001,t,NA()) -> #N/A | AD9: =IF(ABS(t-ROUND(t,0))<0.001,pos_x,NA()) -> #N/A | AE9: =IF(t<T_para, pos_z, NA()) -> 357.4801 | AG9: =IF(AND(L8<L_rampe,Poussee<Poids*SIN(M8)),0,(-W8+Poussee)/m-Poids*SIN(M8)/m) -> 73.988107 | AH9: =IF(AND(L8<L_rampe,Poussee<Poids*SIN(M8)), g*SIN(M8), (-W8+Poussee)/m) -> 83.346647
A10: =IF(B9+0.01<=T_ini+ROUNDUP(Temps_fin_propu,0), 0.01, IF(K9>0, 0.1, 0.0001)) -> 0.01 | B10: =B9+pas -> 3.76 | D10: =IF(AND(L9<L_rampe,Poussee<Poids*SIN(M9)),0,(-W9+Poussee)/m*COS(M9)-U9/m*SIN(M9)) -> 27.825547 | E10: =IF(AND(L9<L_rampe,Poussee<Poids*SIN(M9)),0,(-W9+Poussee)/m*SIN(M9)+U9/m*COS(M9)-Poids/m) -> 78.589209 | F10: =SQRT(acc_x^2+acc_z^2) -> 83.369808 | G10: =G9+acc_x*pas -> 22.649427 | H10: =H9+acc_z*pas -> 71.85705 | I10: =SQRT(vit_x^2+vit_z^2) -> 75.342101 | J10: =J9+0.5*(vit_x+G9)*pas*(K9>=0) -> 87.756136 | K10: =K9+0.5*(vit_z+H9)*pas -> 358.19474 | L10: =SQRT(pos_x^2+pos_z^2) -> 368.78803 | M10: =IF(AND(L9>L_rampe,G10>0),ATAN2(G10,H10),$M$4) -> 1.2654525 | N10: =DEGREES(Beta) -> 72.505087 | P10: =MATCH(t-pas/2-T_ini,CdP_t) -> 2 | Q10: =(INDEX(CdP,2,i_P+1)-INDEX(CdP,2,i_P+0))/(INDEX(CdP,1,i_P+1)-INDEX(CdP,1,i_P+0))*(t-pas/2-T_ini-INDEX(CdP,1,i_P+0))+INDEX(CdP,2,i_P+0) -> 891.94444 | R10: =Poussee/(g*ISP) -> 0.44762536 | S10: =S9-Débit*pas -> 9.4693199 | T10: =m*g -> 92.894028 | U10: =IF(pos_xz<L_rampe,Poids*COS(Beta),0) -> 0 | V10: =Rho_moyen*(20000-Alt_rampe-pos_z)/(20000+Alt_rampe+pos_z) -> 1.1818932 | W10: =1/2*Rho*Sref*Cx*vit_xz^2 -> 14.696132 | Y10: =IF(AND(pos_z<=0,K9>0),"Impact balistique","") & IF(AND(H11<0,vit_z>=0),"Apogée","") & IF(AND(Poussee=0,Q9>0),"Fin de propulsion","") & IF(AND(L11>L_rampe,pos_xz<=L_rampe),"Sortie de rampe","") | Z10: =IF(ABS(t-T_para)<pas/2,"Para","") | AA10: =IF(ABS(t-T_satellite)<pas/2,"Satellite","") | AC10: =IF(ABS(t-ROUND(t,0))<0.001,t,NA()) -> #N/A | AD10: =IF(ABS(t-ROUND(t,0))<0.001,pos_x,NA()) -> #N/A | AE10: =IF(t<T_para, pos_z, NA()) -> 358.19474 | AG10: =IF(AND(L9<L_rampe,Poussee<Poids*SIN(M9)),0,(-W9+Poussee)/m-Poids*SIN(M9)/m) -> 83.317761 | AH10: =IF(AND(L9<L_rampe,Poussee<Poids*SIN(M9)), g*SIN(M9), (-W9+Poussee)/m) -> 92.675138
A11: =IF(B10+0.01<=T_ini+ROUNDUP(Temps_fin_propu,0), 0.01, IF(K10>0, 0.1, 0.0001)) -> 0.01 | B11: =B10+pas -> 3.77 | D11: =IF(AND(L10<L_rampe,Poussee<Poids*SIN(M10)),0,(-W10+Poussee)/m*COS(M10)-U10/m*SIN(M10)) -> 27.795962 | E11: =IF(AND(L10<L_rampe,Poussee<Poids*SIN(M10)),0,(-W10+Poussee)/m*SIN(M10)+U10/m*COS(M10)-Poids/m) -> 78.374829 | F11: =SQRT(acc_x^2+acc_z^2) -> 83.157857 | G11: =G10+acc_x*pas -> 22.927386 | H11: =H10+acc_z*pas -> 72.640798 | I11: =SQRT(vit_x^2+vit_z^2) -> 76.173162 | J11: =J10+0.5*(vit_x+G10)*pas*(K10>=0) -> 87.98402 | K11: =K10+0.5*(vit_z+H10)*pas -> 358.91723 | L11: =SQRT(pos_x^2+pos_z^2) -> 369.544 | M11: =IF(AND(L10>L_rampe,G11>0),ATAN2(G11,H11),$M$4) -> 1.2650653 | N11: =DEGREES(Beta) -> 72.482905 | P11: =MATCH(t-pas/2-T_ini,CdP_t) -> 2 | Q11: =(INDEX(CdP,2,i_P+1)-INDEX(CdP,2,i_P+0))/(INDEX(CdP,1,i_P+1)-INDEX(CdP,1,i_P+0))*(t-pas/2-T_ini-INDEX(CdP,1,i_P+0))+INDEX(CdP,2,i_P+0) -> 889.83333 | R11: =Poussee/(g*ISP) -> 0.44656589 | S11: =S10-Débit*pas -> 9.4648542 | T11: =m*g -> 92.85022 | U11: =IF(pos_xz<L_rampe,Poids*COS(Beta),0) -> 0 | V11: =Rho_moyen*(20000-Alt_rampe-pos_z)/(20000+Alt_rampe+pos_z) -> 1.1818078 | W11: =1/2*Rho*Sref*Cx*vit_xz^2 -> 15.021046 | Y11: =IF(AND(pos_z<=0,K10>0),"Impact balistique","") & IF(AND(H12<0,vit_z>=0),"Apogée","") & IF(AND(Poussee=0,Q10>0),"Fin de propulsion","") & IF(AND(L12>L_rampe,pos_xz<=L_rampe),"Sortie de rampe","") | Z11: =IF(ABS(t-T_para)<pas/2,"Para","") | AA11: =IF(ABS(t-T_satellite)<pas/2,"Satellite","") | AC11: =IF(ABS(t-ROUND(t,0))<0.001,t,NA()) -> #N/A | AD11: =IF(ABS(t-ROUND(t,0))<0.001,pos_x,NA()) -> #N/A | AE11: =IF(t<T_para, pos_z, NA()) -> 358.91723 | AG11: =IF(AND(L10<L_rampe,Poussee<Poids*SIN(M10)),0,(-W10+Poussee)/m-Poids*SIN(M10)/m) -> 83.105548 | AH11: =IF(AND(L10<L_rampe,Poussee<Poids*SIN(M10)), g*SIN(M10), (-W10+Poussee)/m) -> 92.461773
A12: =IF(B11+0.01<=T_ini+ROUNDUP(Temps_fin_propu,0), 0.01, IF(K11>0, 0.1, 0.0001)) -> 0.01 | B12: =B11+pas -> 3.78 | D12: =IF(AND(L11<L_rampe,Poussee<Poids*SIN(M11)),0,(-W11+Poussee)/m*COS(M11)-U11/m*SIN(M11)) -> 27.765702 | E12: =IF(AND(L11<L_rampe,Poussee<Poids*SIN(M11)),0,(-W11+Poussee)/m*SIN(M11)+U11/m*COS(M11)-Poids/m) -> 78.160027 | F12: =SQRT(acc_x^2+acc_z^2) -> 82.945308 | G12: =G11+acc_x*pas -> 23.205043 | H12: =H11+acc_z*pas -> 73.422399 | I12: =SQRT(vit_x^2+vit_z^2) -> 77.002095 | J12: =J11+0.5*(vit_x+G11)*pas*(K11>=0) -> 88.214682 | K12: =K11+0.5*(vit_z+H11)*pas -> 359.64754 | L12: =SQRT(pos_x^2+pos_z^2) -> 370.30823 | M12: =IF(AND(L11>L_rampe,G12>0),ATAN2(G12,H12),$M$4) -> 1.2646819 | N12: =DEGREES(Beta) -> 72.460934 | P12: =MATCH(t-pas/2-T_ini,CdP_t) -> 2 | Q12: =(INDEX(CdP,2,i_P+1)-INDEX(CdP,2,i_P+0))/(INDEX(CdP,1,i_P+1)-INDEX(CdP,1,i_P+0))*(t-pas/2-T_ini-INDEX(CdP,1,i_P+0))+INDEX(CdP,2,i_P+0) -> 887.72222 | R12: =Poussee/(g*ISP) -> 0.44550642 | S12: =S11-Débit*pas -> 9.4603991 | T12: =m*g -> 92.806516 | U12: =IF(pos_xz<L_rampe,Poids*COS(Beta),0) -> 0 | V12: =Rho_moyen*(20000-Alt_rampe-pos_z)/(20000+Alt_rampe+pos_z) -> 1.1817214 | W12: =1/2*Rho*Sref*Cx*vit_xz^2 -> 15.348628 | Y12: =IF(AND(pos_z<=0,K11>0),"Impact balistique","") & IF(AND(H13<0,vit_z>=0),"Apogée","") & IF(AND(Poussee=0,Q11>0),"Fin de propulsion","") & IF(AND(L13>L_rampe,pos_xz<=L_rampe),"Sortie de rampe","") | Z12: =IF(ABS(t-T_para)<pas/2,"Para","") | AA12: =IF(ABS(t-T_satellite)<pas/2,"Satellite","") | AC12: =IF(ABS(t-ROUND(t,0))<0.001,t,NA()) -> #N/A | AD12: =IF(ABS(t-ROUND(t,0))<0.001,pos_x,NA()) -> #N/A | AE12: =IF(t<T_para, pos_z, NA()) -> 359.64754 | AG12: =IF(AND(L11<L_rampe,Poussee<Poids*SIN(M11)),0,(-W11+Poussee)/m-Poids*SIN(M11)/m) -> 82.892735 | AH12: =IF(AND(L11<L_rampe,Poussee<Poids*SIN(M11)), g*SIN(M11), (-W11+Poussee)/m) -> 92.247818
A13: =IF(B12+0.01<=T_ini+ROUNDUP(Temps_fin_propu,0), 0.01, IF(K12>0, 0.1, 0.0001)) -> 0.01 | B13: =B12+pas -> 3.79 | D13: =IF(AND(L12<L_rampe,Poussee<Poids*SIN(M12)),0,(-W12+Poussee)/m*COS(M12)-U12/m*SIN(M12)) -> 27.73478 | E13: =IF(AND(L12<L_rampe,Poussee<Poids*SIN(M12)),0,(-W12+Poussee)/m*SIN(M12)+U12/m*COS(M12)-Poids/m) -> 77.944805 | F13: =SQRT(acc_x^2+acc_z^2) -> 82.732162 | G13: =G12+acc_x*pas -> 23.482391 | H13: =H12+acc_z*pas -> 74.201847 | I13: =SQRT(vit_x^2+vit_z^2) -> 77.828894 | J13: =J12+0.5*(vit_x+G12)*pas*(K12>=0) -> 88.448119 | K13: =K12+0.5*(vit_z+H12)*pas -> 360.38567 | L13: =SQRT(pos_x^2+pos_z^2) -> 371.08072 | M13: =IF(AND(L12>L_rampe,G13>0),ATAN2(G13,H13),$M$4) -> 1.264302 | N13: =DEGREES(Beta) -> 72.439171 | P13: =MATCH(t-pas/2-T_ini,CdP_t) -> 2 | Q13: =(INDEX(CdP,2,i_P+1)-INDEX(CdP,2,i_P+0))/(INDEX(CdP,1,i_P+1)-INDEX(CdP,1,i_P+0))*(t-pas/2-T_ini-INDEX(CdP,1,i_P+0))+INDEX(CdP,2,i_P+0) -> 885.61111 | R13: =Poussee/(g*ISP) -> 0.44444695 | S13: =S12-Débit*pas -> 9.4559547 | T13: =m*g -> 92.762915 | U13: =IF(pos_xz<L_rampe,Poids*COS(Beta),0) -> 0 | V13: =Rho_moyen*(20000-Alt_rampe-pos_z)/(20000+Alt_rampe+pos_z) -> 1.1816342 | W13: =1/2*Rho*Sref*Cx*vit_xz^2 -> 15.678847 | Y13: =IF(AND(pos_z<=0,K12>0),"Impact balistique","") & IF(AND(H14<0,vit_z>=0),"Apogée","") & IF(AND(Poussee=0,Q12>0),"Fin de propulsion","") & IF(AND(L14>L_rampe,pos_xz<=L_rampe),"Sortie de rampe","") | Z13: =IF(ABS(t-T_para)<pas/2,"Para","") | AA13: =IF(ABS(t-T_satellite)<pas/2,"Satellite","") | AC13: =IF(ABS(t-ROUND(t,0))<0.001,t,NA()) -> #N/A | AD13: =IF(ABS(t-ROUND(t,0))<0.001,pos_x,NA()) -> #N/A | AE13: =IF(t<T_para, pos_z, NA()) -> 360.38567 | AG13: =IF(AND(L12<L_rampe,Poussee<Poids*SIN(M12)),0,(-W12+Poussee)/m-Poids*SIN(M12)/m) -> 82.679326 | AH13: =IF(AND(L12<L_rampe,Poussee<Poids*SIN(M12)), g*SIN(M12), (-W12+Poussee)/m) -> 92.033276
